<?xml version="1.0" ?>
<robot xmlns:xacro="http://ros.org/wiki/xacro" name="tflow">

    <xacro:property name="dynamixel_mx28_x" value="0.0356"/>
    <xacro:property name="dynamixel_mx28_y" value="0.0355"/>
    <xacro:property name="dynamixel_mx28_z" value="0.0506"/>
    <xacro:property name="dynamixel_mx28_weight" value="0.072"/>

    <xacro:property name="dynamixel_mx64_x" value="0.0402"/>
    <xacro:property name="dynamixel_mx64_y" value="0.041"/>
    <xacro:property name="dynamixel_mx64_z" value="0.0611"/>
    <xacro:property name="dynamixel_mx64_weight" value="0.126"/>

    <xacro:property name="dynamixel_mx106_x" value="0.0402"/>
    <xacro:property name="dynamixel_mx106_y" value="0.046"/>
    <xacro:property name="dynamixel_mx106_z" value="0.0651"/>
    <xacro:property name="dynamixel_mx106_weight" value="0.153"/>

    <xacro:property name="kepalakepala_y" value="0.046"/>
    <xacro:property name="kepalakepala_z" value="0.0651"/>
    <xacro:property name="kepalakepala_weight" value="0.153"/>

    <xacro:macro name="kepalakepala" params="roll pitch yaw x y z">
        <visual>
            <geometry>
                <box size="${kepalakepala_x} ${kepalakepala_y} ${kepalakepala_z}"/>
            </geometry>
            <origin rpy="${roll} ${pitch} ${yaw}" xyz="${x} ${y} ${z}"/>
            <material name="silver">
                <color rgba="0.5 0.5 0.5 1"/>
            </material>
        </visual>
        <collision>
          <geometry>
            <box size="${kepalakepala_x} ${kepalakepala_y} ${kepalakepala_z}"/>
          </geometry>
          <origin rpy="${roll} ${pitch} ${yaw}" xyz="${x} ${y} ${z}"/>
        </collision>
        <inertial>
            <mass value="${kepalakepala_weight}"/>
            <inertia ixx="0.0" ixy="0.0" ixz="0.0" iyy="0.0" iyz="0.0" izz="0.0"/>
        </inertial>
    </xacro:macro>

    <xacro:macro name="dynamixelmx28" params="roll pitch yaw x y z">
        <visual>
            <geometry>
                <box size="${dynamixel_mx28_x} ${dynamixel_mx28_y} ${dynamixel_mx28_z}"/>
            </geometry>
            <origin rpy="${roll} ${pitch} ${yaw}" xyz="${x} ${y} ${z}"/>
            <material name="silver">
                <color rgba="0.5 0.5 0.5 1"/>
            </material>
        </visual>
        <collision>
          <geometry>
            <box size="${dynamixel_mx28_x} ${dynamixel_mx28_y} ${dynamixel_mx28_z}"/>
          </geometry>
          <origin rpy="${roll} ${pitch} ${yaw}" xyz="${x} ${y} ${z}"/>
        </collision>
        <inertial>
            <mass value="${dynamixel_mx28_weight}"/>
            <inertia ixx="0.0" ixy="0.0" ixz="0.0" iyy="0.0" iyz="0.0" izz="0.0"/>
        </inertial>
    </xacro:macro>

    <xacro:macro name="dynamixelmx64" params="roll pitch yaw x y z">
        <visual>
            <geometry>
                <box size="${dynamixel_mx64_x} ${dynamixel_mx64_y} ${dynamixel_mx64_z}"/>
            </geometry>
            <origin rpy="${roll} ${pitch} ${yaw}" xyz="${x} ${y} ${z}"/>
            <material name="silver">
                <color rgba="0.5 0.5 0.5 1"/>
            </material>
        </visual>
        <collision>
          <geometry>
            <box size="${dynamixel_mx64_x} ${dynamixel_mx64_y} ${dynamixel_mx64_z}"/>
          </geometry>
          <origin rpy="${roll} ${pitch} ${yaw}" xyz="${x} ${y} ${z}"/>
        </collision>
        <inertial>
            <mass value="${dynamixel_mx64_weight}"/>
            <inertia ixx="0.0" ixy="0.0" ixz="0.0" iyy="0.0" iyz="0.0" izz="0.0"/>
        </inertial>
    </xacro:macro>

    <xacro:macro name="dynamixelmx106" params="roll pitch yaw x y z">
        <visual>
            <geometry>
                <box size="${dynamixel_mx106_x} ${dynamixel_mx106_y} ${dynamixel_mx106_z}"/>
            </geometry>
            <origin rpy="${roll} ${pitch} ${yaw}" xyz="${x} ${y} ${z}"/>
            <material name="silver">
                <color rgba="0.3 0.3 0.3 1"/>
            </material>
        </visual>
        <collision>
          <geometry>
            <box size="${dynamixel_mx106_x} ${dynamixel_mx106_y} ${dynamixel_mx106_z}"/>
          </geometry>
          <origin rpy="${roll} ${pitch} ${yaw}" xyz="${x} ${y} ${z}"/>
        </collision>
        <inertial>
            <mass value="${dynamixel_mx106_weight}"/>
            <inertia ixx="0.0" ixy="0.0" ixz="0.0" iyy="0.0" iyz="0.0" izz="0.0"/>
        </inertial>
    </xacro:macro>

    <xacro:macro name="link_cylinder" params="le r roll pitch yaw x y z">
        <visual>
            <geometry>
                <cylinder length="${le}" radius="${r}"/>
            </geometry>
            <origin rpy="${roll} ${pitch} ${yaw}" xyz="${x} ${y} ${z}"/>
            <material name="white">
                <color rgba="0.8 0.8 0.8 1"/>
            </material>
        </visual>
        <collision>
          <geometry>
            <cylinder length="${le}" radius="${r}"/>
          </geometry>
          <origin rpy="${roll} ${pitch} ${yaw}" xyz="${x} ${y} ${z}"/>
        </collision>
        <inertial>
            <mass value="${le*r}"/>
            <inertia ixx="0.0" ixy="0.0" ixz="0.0" iyy="0.0" iyz="0.0" izz="0.0"/>
        </inertial>
    </xacro:macro>

    <xacro:macro name="link_box" params="bx by bz roll pitch yaw x y z">
        <visual>
            <geometry>
                <box size="${bx} ${by} ${bz}"/>
            </geometry>
            <origin rpy="${roll} ${pitch} ${yaw}" xyz="${x} ${y} ${z}"/>
            <material name="silver">
                <color rgba="0.5 0.5 0.5 1"/>
            </material>
        </visual>
        <collision>
          <geometry>
            <box size="${bx} ${by} ${bz}"/>
          </geometry>
          <origin rpy="${roll} ${pitch} ${yaw}" xyz="${x} ${y} ${z}"/>
        </collision>
        <inertial>
            <mass value="${bx*by*bz}"/>
            <inertia ixx="0.0" ixy="0.0" ixz="0.0" iyy="0.0" iyz="0.0" izz="0.0"/>
        </inertial>
    </xacro:macro>
    
     <xacro:macro name="link_box2" params="bx by bz roll pitch yaw x y z">
        <visual>
            <geometry>
                <box size="${bx} ${by} ${bz}"/>
            </geometry>
            <origin rpy="${roll} ${pitch} ${yaw}" xyz="${x} ${y} ${z}"/>
            <material name="white">
                <color rgba="0.8 0.8 0.8 1"/>
            </material>
        </visual>
        <collision>
          <geometry>
            <box size="${bx} ${by} ${bz}"/>
          </geometry>
          <origin rpy="${roll} ${pitch} ${yaw}" xyz="${x} ${y} ${z}"/>
        </collision>
        <inertial>
            <mass value="${bx*by*bz}"/>
            <inertia ixx="0.0" ixy="0.0" ixz="0.0" iyy="0.0" iyz="0.0" izz="0.0"/>
        </inertial>
    </xacro:macro>

    <xacro:macro name="telapak_tangan" params="le r roll pitch yaw x y z">
        <visual>
            <geometry>
                <cylinder length="${le}" radius="${r}"/>
            </geometry>
            <origin rpy="${roll} ${pitch} ${yaw}" xyz="${x} ${y} ${z}"/>
            <material name="black">
                <color rgba="0 0 0 1"/>
            </material>
        </visual>
        <collision>
          <geometry>
            <cylinder length="${le}" radius="${r}"/>
          </geometry>
          <origin rpy="${roll} ${pitch} ${yaw}" xyz="${x} ${y} ${z}"/>
        </collision>
        <inertial>
            <mass value="${le*r}"/>
            <inertia ixx="0.0" ixy="0.0" ixz="0.0" iyy="0.0" iyz="0.0" izz="0.0"/>
        </inertial>
    </xacro:macro>

    <link name="base_link">
        <visual>
            <geometry>
                <box size="0.19 0.16 0.06"/>
            </geometry>
            <origin rpy="0 0 0" xyz="0 0 0"/>
            <material name="silver">
                <color rgba="0.5 0.5 0.5 1"/>
            </material>
        </visual>
        <collision>
            <geometry>
                <box size="0.19 0.16 0.06"/>
            </geometry>
            <origin rpy="0 0 0" xyz="0 0 0"/>
            <material name="silver">
                <color rgba="0.5 0.5 0.5 1"/>
            </material>
        </collision>
        <inertial>
            <mass value="0.01"/>
            <inertia ixx="0.0" ixy="0.0" ixz="0.0" iyy="0.0" iyz="0.0" izz="0.0"/>
        </inertial>
    </link>

    <!-- PERUT -->
    <link name="servo_perut_pitch">
        <xacro:dynamixelmx64 roll="0.0" pitch="0.0" yaw = "1.57" x="0" y="0" z="0.025"/>
    </link>

    <link name="servo_perut_roll">
        <xacro:dynamixelmx64 roll="0.0" pitch="0.0" yaw = "1.57" x="0" y="0" z="0.025"/>
    </link>

    <link name="alas_badan_atas">
        <xacro:link_box bx="0.174" by="0.115" bz="0.015" roll="0.0" pitch="0.0" yaw ="0" x="0" y="-0.025" z="0.0725"/>
    </link>

    <link name="badan_atas">
        <xacro:link_box bx="0.05" by="0.05" bz="0.05" roll="0.0" pitch="0.0" yaw ="0" x="0" y="0.0" z="0.0"/>
    </link>

    <!-- TANGAN -->

    <link name="servo_lengan_kanan_roll">
        <xacro:dynamixelmx64 roll="1.57" pitch="0.0" yaw = "0.0" x="0" y="0.008" z="0.0"/>
    </link>

    <link name="servo_lengan_kiri_roll">
        <xacro:dynamixelmx64 roll="1.57" pitch="0.0" yaw = "0.0" x="0" y="0.008" z="0.0"/>
    </link>

    <link name="link_servo_lengan_kanan_roll">
        <xacro:link_cylinder le="0.04" r="0.02" roll="0.0" pitch="1.57" yaw ="0.0" x="0.02" y="0" z="0.00"/>
    </link>

    <link name="link_servo_lengan_kiri_roll">
        <xacro:link_cylinder le="0.04" r="0.02" roll="0.0" pitch="-1.57" yaw ="0.0" x="-0.02" y="0" z="0.00"/>
    </link>

    <link name="servo_lengan_kanan_pitch">
        <xacro:dynamixelmx64 roll="0.0" pitch="0.0" yaw = "0.0" x="0" y="0" z="-0.01"/>
    </link>

    <link name="servo_lengan_kiri_pitch">
        <xacro:dynamixelmx64 roll="0.0" pitch="0.0" yaw = "0.0" x="0" y="0" z="-0.01"/>
    </link>

    <link name="tangan_kanan_1">
        <xacro:link_box bx="0.035" by="0.035" bz="0.18" roll="0.0" pitch="0.0" yaw ="0" x="0" y="0.0" z="-0.09"/>
    </link>

    <link name="tangan_kiri_1">
        <xacro:link_box bx="0.035" by="0.035" bz="0.18" roll="0.0" pitch="0.0" yaw ="0" x="0" y="0.0" z="-0.09"/>
    </link>

    <link name="tangan_kanan_2">
        <xacro:link_box bx="0.035" by="0.035" bz="0.13" roll="0.0" pitch="0.0" yaw ="0" x="0" y="0.0" z="-0.065"/>
    </link>

    <link name="tangan_kiri_2">
        <xacro:link_box bx="0.035" by="0.035" bz="0.13" roll="0.0" pitch="0.0" yaw ="0" x="0" y="0.0" z="-0.065"/>
    </link>

    <link name="telapak_tangan_kanan">
        <xacro:telapak_tangan le="0.10" r="0.03" roll="0.0" pitch="0" yaw ="0" x="0" y="0" z="0.0"/>
    </link>

    <link name="telapak_tangan_kiri">
        <xacro:telapak_tangan le="0.10" r="0.03" roll="0.0" pitch="0" yaw ="0" x="0" y="0" z="0.0"/>
    </link>

    <!-- KEPALA -->
    <link name="servo_kepala_yaw">
        <xacro:dynamixelmx28 roll="1.57" pitch="1.57" yaw = "0.0" x="0" y="0.00" z="0.0"/>
    </link>

    <link name="servo_kepala_roll">
        <xacro:dynamixelmx28 roll="0.0" pitch="0.0" yaw = "1.57" x="0" y="0.00" z="0.0"/>
    </link>

    <link name="link_kepala">
        <xacro:link_cylinder le="0.04" r="0.02" roll="0.0" pitch="0.0" yaw ="0.0" x="0.00" y="0" z="0.02"/>
    </link>

    <link name="kepala">
        <xacro:link_box bx="0.17" by="0.06" bz="0.051" roll="0.0" pitch="0.0" yaw ="0" x="0" y="0.0" z="0.0"/>
    </link>

    <link name="kamera_kanan">
        <xacro:link_cylinder le="0.045" r="0.02" roll="1.57" pitch="0.0" yaw ="0.0" x="0.00" y="0.01" z="0.0"/>
    </link>

    <link name="kamera_kiri">
        <xacro:link_cylinder le="0.045" r="0.02" roll="1.57" pitch="0.0" yaw ="0.0" x="0.00" y="0.01" z="0.0"/>
    </link>

    <joint name="1.engkle_kanan_pitch" type="revolute">
        <parent link="servo_engkle_pitch_kanan"/>
        <child link="telapak_kaki_kanan"/>
        <origin xyz="0 0.025 0"/>
        <axis xyz="0 -1 0" />
        <limit effort="300" velocity="0.1" lower="-1.54" upper="1.54"/>
    </joint>

    <joint name="2.engkle_kiri_pitch" type="revolute">
        <parent link="servo_engkle_pitch_kiri"/>
        <child link="telapak_kaki_kiri"/>
        <origin xyz="0 0.025 0"/>
        <axis xyz="0 -1 0" />
        <limit effort="300" velocity="0.1" lower="-1.54" upper="1.54"/>
    </joint>

    <joint name="3.engkle_kanan_roll" type="revolute"> 
        <parent link="link_betis_kanan"/>
        <child link="servo_engkle_roll_kanan"/>
        <origin xyz="0 0.0 -0.15"/>
        <axis xyz="-1 0 0" />
        <limit effort="300" velocity="0.1" lower="-1.57" upper="1.57"/>
    </joint>

    <joint name="4.engkle_kiri_roll" type="revolute">
        <parent link="link_betis_kiri"/>
        <child link="servo_engkle_roll_kiri"/>
        <origin xyz="0 0.0 -0.15"/>
        <axis xyz="1 0 0" />
        <limit effort="300" velocity="0.1" lower="-1.57" upper="1.57"/>
    </joint>

    <joint name="5.lutut_kanan_roll" type="revolute">
        <parent link="servo_lutut_kanan"/>
        <child link="link_betis_kanan"/>
        <origin xyz="0 0.0 -0.022"/>
        <axis xyz="1 0 0" />
        <limit effort="300" velocity="0.1" lower="-3.14" upper="3.14"/>
    </joint>

    <joint name="6.lutut_kiri_roll" type="revolute">
        <parent link="servo_lutut_kiri"/>
        <child link="link_betis_kiri"/>
        <origin xyz="0 0.0 -0.022"/>
        <axis xyz="-1 0 0" />
        <limit effort="300" velocity="0.1" lower="-3.14" upper="3.14"/>
    </joint>

    <joint name="7.hip_kanan_roll" type="revolute">
        <parent link="servo_hip_roll_kanan"/>
        <child link="link_paha_kanan"/>
        <origin xyz="0 0.0 -0.01"/>
        <axis xyz="1 0 0" />
        <limit effort="300" velocity="0.1" lower="-1.57" upper="1.57"/>
    </joint>

    <joint name="8.hip_kiri_roll" type="revolute">
        <parent link="servo_hip_roll_kiri"/>
        <child link="link_paha_kiri"/>
        <origin xyz="0 0 -0.01"/>
        <axis xyz="-1 0 0" />
        <limit effort="300" velocity="0.1" lower="-1.57" upper="1.57"/>
    </joint>

    <joint name="9.hip_kanan_pitch" type="revolute">
        <parent link="servo_hip_pitch_kanan"/>
        <child link="servo_hip_roll_kanan"/>
        <origin xyz="0 0.02 0"/>
        <axis xyz="0 1 0" />
        <limit effort="300" velocity="0.1" lower="-1.57" upper="1.57"/>
    </joint>

    <joint name="10.hip_kiri_pitch" type="revolute">
        <parent link="servo_hip_pitch_kiri"/>
        <child link="servo_hip_roll_kiri"/>
        <origin xyz="0 0.02 0"/>
        <axis xyz="0 1 0" />
        <limit effort="300" velocity="0.1" lower="-1.57" upper="1.57"/>
    </joint>

    <joint name="11.hip_kanan_yaw" type="revolute">
        <parent link="servo_hip_yaw_kanan"/>
        <child link="servo_hip_pitch_kanan"/>
        <origin xyz="0 0 -0.060"/>
        <axis xyz="0 0 -1" />
        <limit effort="300" velocity="0.1" lower="-1.57" upper="1.57"/>
    </joint>

    <joint name="12.hip_kiri_yaw" type="revolute">
        <parent link="servo_hip_yaw_kiri"/>
        <child link="servo_hip_pitch_kiri"/>
        <origin xyz="0 0 -0.060"/>
        <axis xyz="0 0 -1" />
        <limit effort="300" velocity="0.1" lower="-1.57" upper="1.57"/>
    </joint>

   <joint name="13.joint_perut_pitch" type="revolute">
        <parent link="base_link"/>
        <child link="servo_perut_pitch"/>
        <origin rpy="0 0 0" xyz="0.00 -0.01 0.061"/>
        <limit effort="300" velocity="0.1" lower="-1.57" upper="1.57"/>
        <dynamics damping="50" friction="1"/>
        <axis xyz="0 1 0" />
    </joint>

   <joint name="14.joint_perut_roll" type="revolute">
        <parent link="servo_perut_roll"/>
        <child link="alas_badan_atas"/>
        <origin rpy="0 0 0" xyz="0.00 0.00 0.035"/>
        <limit effort="300" velocity="0.1" lower="-1.57" upper="1.57"/>
        <dynamics damping="50" friction="1"/>
        <axis xyz="1 0 0" />
    </joint>

   <joint name="15.tangan_kanan_roll" type="revolute">
        <parent link="servo_lengan_kanan_roll"/>
        <child link="link_servo_lengan_kanan_roll"/>
        <origin rpy="0 0 0" xyz="0.0 0.0 0.0"/>
        <limit effort="300" velocity="0.1" lower="-1.57" upper="1.57"/>
        <dynamics damping="50" friction="1"/>
        <axis xyz="1 0 0" />
    </joint>

   <joint name="16.tangan_kiri_roll" type="revolute">
        <parent link="servo_lengan_kiri_roll"/>
        <child link="link_servo_lengan_kiri_roll"/>
        <origin rpy="0 0 0" xyz="0.0 0.0 0.0"/>
        <limit effort="300" velocity="0.1" lower="-1.57" upper="1.57"/>
        <dynamics damping="50" friction="1"/>
        <axis xyz="-1 0 0" />
    </joint>

    <joint name="17.tangan_kanan_pitch" type="revolute">
        <parent link="link_servo_lengan_kanan_roll"/>
        <child link="servo_lengan_kanan_pitch"/>
        <origin rpy="0 0 0" xyz="0.058 0.0 0.0"/>
        <limit effort="300" velocity="0.1" lower="-1.57" upper="1.57"/>
        <dynamics damping="50" friction="1"/>
        <axis xyz="0 -1 0" />
    </joint>

    <joint name="18.tangan_kiri_pitch" type="revolute">
        <parent link="link_servo_lengan_kiri_roll"/>
        <child link="servo_lengan_kiri_pitch"/>
        <origin rpy="0 0 0" xyz="-0.058 0.0 0.0"/>
        <limit effort="300" velocity="0.1" lower="-1.57" upper="1.57"/>
        <dynamics damping="50" friction="1"/>
        <axis xyz="0 -1 0" />
    </joint>

   <joint name="19.kepala_yaw" type="revolute">
        <parent link="servo_kepala_yaw"/>
        <child link="servo_kepala_roll"/>
        <origin rpy="0 0 0" xyz="0.0 0.0 0.05"/>
        <limit effort="300" velocity="0.1" lower="-1.57" upper="1.57"/>
        <dynamics damping="50" friction="1"/>
        <axis xyz="0 0 1" />
    </joint>

    <joint name="20.kepala_roll" type="revolute">
        <parent link="servo_kepala_roll"/>
        <child link="link_kepala"/>
        <origin rpy="0 0 0" xyz="0.0 0.0 0.0"/>
        <limit effort="300" velocity="0.1" lower="-1.57" upper="1.57"/>
        <dynamics damping="50" friction="1"/>
        <axis xyz="1 0 0" />
    </joint>
   

    <!-- PERUT -->
    
    <joint name="servo_joint_perut_roll" type="fixed">
        <parent link="servo_perut_pitch"/>
        <child link="servo_perut_roll"/>
        <origin rpy="0 0 0" xyz="0.00 0.05 0.00"/>
        <limit effort="300" velocity="0.1" lower="-1.57" upper="1.57"/>
        <dynamics damping="50" friction="1"/>
        <axis xyz="1 0 0" />
    </joint>

    <joint name="badan_atas_fix" type="fixed">
        <parent link="alas_badan_atas"/>
        <child link="badan_atas"/>
        <origin rpy="0 0 0" xyz="0.00 -0.025 0.1175"/>
        <limit effort="300" velocity="0.1" lower="-1.57" upper="1.57"/>
        <dynamics damping="50" friction="1"/>
        <axis xyz="1 0 0" />
    </joint>

    <!-- TANGAN -->

    <joint name="badan_to_tangan_kanan" type="fixed">
        <parent link="badan_atas"/>
        <child link="servo_lengan_kanan_roll"/>
        <origin rpy="0 0 0" xyz="0.067 0.0 0.0"/>
        <limit effort="300" velocity="0.1" lower="-1.57" upper="1.57"/>
        <dynamics damping="50" friction="1"/>
        <axis xyz="1 0 0" />
    </joint>

    <joint name="badan_to_tangan_kiri" type="fixed">
        <parent link="badan_atas"/>
        <child link="servo_lengan_kiri_roll"/>
        <origin rpy="0 0 0" xyz="-0.067 0.0 0.0"/>
        <limit effort="300" velocity="0.1" lower="-1.57" upper="1.57"/>
        <dynamics damping="50" friction="1"/>
        <axis xyz="1 0 0" />
    </joint>

    <joint name="joint_tangan_kanan_1" type="fixed">
        <parent link="servo_lengan_kanan_pitch"/>
        <child link="tangan_kanan_1"/>
        <origin rpy="0 0 0" xyz="0.0 0.0 -0.015"/>
        <limit effort="300" velocity="0.1" lower="-1.57" upper="1.57"/>
        <dynamics damping="50" friction="1"/>
        <axis xyz="0 1 0" />
    </joint>

    <joint name="joint_tangan_kiri_1" type="fixed">
        <parent link="servo_lengan_kiri_pitch"/>
        <child link="tangan_kiri_1"/>
        <origin rpy="0 0 0" xyz="0.0 0.0 -0.015"/>
        <limit effort="300" velocity="0.1" lower="-1.57" upper="1.57"/>
        <dynamics damping="50" friction="1"/>
        <axis xyz="0 1 0" />
    </joint>

    <joint name="joint_tangan_kanan_2" type="fixed">
        <parent link="tangan_kanan_1"/>
        <child link="tangan_kanan_2"/>
        <origin rpy="0.61 0 0" xyz="0.0 0.0 -0.18"/>
        <limit effort="300" velocity="0.1" lower="-1.57" upper="1.57"/>
        <dynamics damping="50" friction="1"/>
        <axis xyz="0 1 0" />
    </joint>

    <joint name="joint_tangan_kiri_2" type="fixed">
        <parent link="tangan_kiri_1"/>
        <child link="tangan_kiri_2"/>
        <origin rpy="0.61 0 0" xyz="0.0 0.0 -0.18"/>
        <limit effort="300" velocity="0.1" lower="-1.57" upper="1.57"/>
        <dynamics damping="50" friction="1"/>
        <axis xyz="0 1 0" />
    </joint>

    <joint name="tangan_kanan_eof" type="fixed">
        <parent link="tangan_kanan_2"/>
        <child link="telapak_tangan_kanan"/>
        <origin rpy="0.0 0 0" xyz="0.0 0.0 ${-0.13 - 0.05}"/>
        <limit effort="300" velocity="0.1" lower="-1.57" upper="1.57"/>
        <dynamics damping="50" friction="1"/>
        <axis xyz="0 1 0" />
    </joint>

    <joint name="tangan_kiri_eof" type="fixed">
        <parent link="tangan_kiri_2"/>
        <child link="telapak_tangan_kiri"/>
        <origin rpy="0.0 0 0" xyz="0.0 0.0 ${-0.13 - 0.05}"/>
        <limit effort="300" velocity="0.1" lower="-1.57" upper="1.57"/>
        <dynamics damping="50" friction="1"/>
        <axis xyz="0 1 0" />
    </joint>

    <!-- KEPALA -->

    <joint name="badan_to_tangan_kepala" type="fixed">
        <parent link="badan_atas"/>
        <child link="servo_kepala_yaw"/>
        <origin rpy="0 0 0" xyz="0.0 0.0 0.03"/>
        <limit effort="300" velocity="0.1" lower="-1.57" upper="1.57"/>
        <dynamics damping="50" friction="1"/>
        <axis xyz="1 0 0" />
    </joint>

    <joint name="kepala_eof" type="fixed">
        <parent link="link_kepala"/>
        <child link="kepala"/>
        <origin rpy="0 0 0" xyz="0.0 0.0 0.05"/>
        <limit effort="300" velocity="0.1" lower="-1.57" upper="1.57"/>
        <dynamics damping="50" friction="1"/>
        <axis xyz="0 0 1" />
    </joint>

    <joint name="kamera_kanan_eof" type="fixed">
        <parent link="kepala"/>
        <child link="kamera_kanan"/>
        <origin rpy="0 0 0" xyz="0.05 0.0 0.00"/>
        <limit effort="300" velocity="0.1" lower="-1.57" upper="1.57"/>
        <dynamics damping="50" friction="1"/>
        <axis xyz="0 0 1" />
    </joint>

    <joint name="kamera_kiri_eof" type="fixed">
        <parent link="kepala"/>
        <child link="kamera_kiri"/>
        <origin rpy="0 0 0" xyz="-0.05 0.0 0.00"/>
        <limit effort="300" velocity="0.1" lower="-1.57" upper="1.57"/>
        <dynamics damping="50" friction="1"/>
        <axis xyz="0 0 1" />
    </joint>

    <!-- Kaki Kanan -->

    <joint name="base_to_hip_kanan" type="fixed">
        <parent link="base_link"/>
        <child link="servo_hip_yaw_kanan"/>
        <origin xyz="0.053 0 0."/>
        <axis xyz="0 0 1" />
    </joint>

    <link name="servo_hip_yaw_kanan">
      <visual>
        <geometry>
          <box size="0.042 0.061 0.042"/>
        </geometry>
        <origin rpy="0 0 0" xyz="0 0 0"/>
        <material name="silver">
          <color rgba="0.5 0.5 0.5 1"/>
        </material>
      </visual>
      <collision>
        <geometry>
          <box size="0.042 0.042 0.042"/>
        </geometry>
        <origin rpy="0 0 0" xyz="0 0 0"/>
      </collision>
      <inertial>
          <mass value="1"/>
          <inertia ixx="1.0" ixy="0.0" ixz="0.0" iyy="1.0" iyz="0.0" izz="1.0"/>
      </inertial>
    </link>

    <link name="servo_hip_pitch_kanan">
      <visual>
        <geometry>
          <box size="0.042 0.042 0.061"/>
        </geometry>
        <origin rpy="0 0 0" xyz="0 -0.03 0"/>
        <material name="silver">
          <color rgba="0.5 0.5 0.5 1"/>
        </material>
      </visual>
      <collision>
        <geometry>
          <box size="0.042 0.042 0.042"/>
        </geometry>
        <origin rpy="0 0 0" xyz="0 0 0"/>
      </collision>
      <inertial>
          <mass value="1"/>
          <inertia ixx="1.0" ixy="0.0" ixz="0.0" iyy="1.0" iyz="0.0" izz="1.0"/>
      </inertial>
    </link>

    <link name="servo_hip_roll_kanan">
      <visual>
        <geometry>
          <box size="0.042 0.042 0.061"/>
        </geometry>
        <origin rpy="0 0 0" xyz="0 0 0"/>
        <material name="silver">
          <color rgba="0.5 0.5 0.5 1"/>
        </material>
      </visual>
      <collision>
        <geometry>
          <box size="0.042 0.042 0.042"/>
        </geometry>
        <origin rpy="0 0 0" xyz="0 0 0"/>
      </collision>
      <inertial>
          <mass value="1"/>
          <inertia ixx="1.0" ixy="0.0" ixz="0.0" iyy="1.0" iyz="0.0" izz="1.0"/>
      </inertial>
    </link>
    
    <link name="link_paha_kanan">
      <visual>
        <geometry>
          <box size="0.042 0.042 0.192"/>
        </geometry>
        <origin rpy="0 0 0" xyz="0 0 -0.09"/>
        <material name="silver">
          <color rgba="0.5 0.5 0.5 1"/>
        </material>
      </visual>
      <collision>
        <geometry>
          <box size="0.042 0.042 0.192"/>
        </geometry>
        <origin rpy="0 0 0" xyz="0 0 -0.09"/>
      </collision>
      <inertial>
          <mass value="1"/>
          <inertia ixx="1.0" ixy="0.0" ixz="0.0" iyy="1.0" iyz="0.0" izz="1.0"/>
      </inertial>
    </link>

    <joint name="link_servo_lutut_kanan" type="fixed">
        <parent link="link_paha_kanan"/>
        <child link="servo_lutut_kanan"/>
        <origin xyz="0 0.0 -0.15 "/>
        <axis xyz="1 0 0" />
        <limit effort="300" velocity="0.1" lower="-1.57" upper="1.57"/>
    </joint>

    <link name="servo_lutut_kanan">
      <visual>
        <geometry>
          <box size="0.042 0.042 0.061"/>
        </geometry>
        <origin rpy="0 0 0" xyz="0 0 0"/>
        <material name="silver">
          <color rgba="0.5 0.5 0.5 1"/>
        </material>
      </visual>
      <collision>
        <geometry>
          <box size="0.042 0.042 0.061"/>
        </geometry>
        <origin rpy="0 0 0" xyz="0 0 0"/>
      </collision>
      <inertial>
          <mass value="1"/>
          <inertia ixx="1.0" ixy="0.0" ixz="0.0" iyy="1.0" iyz="0.0" izz="1.0"/>
      </inertial>
    </link>

    <link name="link_betis_kanan">
      <visual>
        <geometry>
          <box size="0.042 0.042 0.192"/>
        </geometry>
        <origin rpy="0 0 0" xyz="0 0 -0.09"/>
        <material name="silver">
          <color rgba="0.5 0.5 0.5 11"/>
        </material>
      </visual>
      <collision>
        <geometry>
          <box size="0.042 0.042 0.192"/>
        </geometry>
        <origin rpy="0 0 0" xyz="0 0 -0.09"/>
      </collision>
      <inertial>
          <mass value="1"/>
          <inertia ixx="1.0" ixy="0.0" ixz="0.0" iyy="1.0" iyz="0.0" izz="1.0"/>
      </inertial>
    </link>

    

    <link name="servo_engkle_roll_kanan">
      <visual>
        <geometry>
          <box size="0 0 0"/>
        </geometry>
        <origin rpy="0 0 0" xyz="0 0 0"/>
        <material name="silver">
          <color rgba="0.5 0.5 0.5 1"/>
        </material>
      </visual>
      <collision>
        <geometry>
          <box size="0 0 0"/>
        </geometry>
        <origin rpy="0 0 0" xyz="0 0 0"/>
      </collision>
      <inertial>
          <mass value="1"/>
          <inertia ixx="1.0" ixy="0.0" ixz="0.0" iyy="1.0" iyz="0.0" izz="1.0"/>
      </inertial>
    </link>

    <joint name="link_servo_engkle_kanan" type="fixed">
        <parent link="servo_engkle_roll_kanan"/>
        <child link="servo_engkle_pitch_kanan"/>
        <origin xyz="0 -0.051 0"/>
        <axis xyz="1 0 0" />
        <limit effort="300" velocity="0.1" lower="-3.14" upper="3.14"/>
    </joint>

    <link name="servo_engkle_pitch_kanan">
      <visual>
        <geometry>
          <box size="0.042 0.042 0.061"/>
        </geometry>
        <origin rpy="0 0 0" xyz="0 0 0"/>
        <material name="silver">
          <color rgba="0.5 0.5 0.5 1"/>
        </material>
      </visual>
      <collision>
        <geometry>
          <box size="0.042 0.042 0.061"/>
        </geometry>
        <origin rpy="0 0 0" xyz="0 0 0"/>
      </collision>
      <inertial>
          <mass value="1"/>
          <inertia ixx="1.0" ixy="0.0" ixz="0.0" iyy="1.0" iyz="0.0" izz="1.0"/>
      </inertial>
    </link>

    <link name="telapak_kaki_kanan">
      <visual>
        <geometry>
          <box size="0.129 0.219 0.005"/>
        </geometry>
        <origin rpy="0 0 0" xyz="0.0170 0 -0.056"/>
        <material name="silver">
          <color rgba="0.5 0.5 0.5 1"/>
        </material>
      </visual>
      <collision>
        <geometry>
          <box size="0.129 0.219 0.005"/>
        </geometry>
        <origin rpy="0 0 0" xyz="0.0170 0 -0.056"/>
      </collision>
      <inertial>
          <mass value="1"/>
          <inertia ixx="1.0" ixy="0.0" ixz="0.0" iyy="1.0" iyz="0.0" izz="1.0"/>
      </inertial>
    </link>

    <joint name="kaki_kanan_eof" type="fixed">
        <parent link="telapak_kaki_kanan"/>
        <child link="telapak_kaki_kanan_eof"/>
        <origin xyz="0 0.0 -0.055"/>
        <axis xyz="0 1 0" />
        <limit effort="300" velocity="0.1" lower="-3.14" upper="3.14"/>
    </joint>

    <link name="telapak_kaki_kanan_eof">
      <visual>
        <geometry>
          <box size="0.129 0.005 0.030"/>
        </geometry>
        <origin rpy="0 0 0" xyz="0.0170 0.107 0.017"/>
            <material name="black">
                <color rgba="0 0 0 1"/>
            </material>
      </visual>
      <collision>
        <geometry>
          <box size="0.129 0.005 0.030"/>
        </geometry>
         <origin rpy="0 0 0" xyz="0.0170 0.107 0.017"/>
      </collision>
      <inertial>
          <mass value="1"/>
          <inertia ixx="1.0" ixy="0.0" ixz="0.0" iyy="1.0" iyz="0.0" izz="1.0"/>
      </inertial>
    </link>

<!--Kaki kiri-->

    <joint name="base_to_hip_kiri" type="fixed">
        <parent link="base_link"/>
        <child link="servo_hip_yaw_kiri"/>
        <origin xyz="-0.053 0 0"/>
        <axis xyz="0 0 1" />
    </joint>

    <link name="servo_hip_yaw_kiri">
      <visual>
        <geometry>
          <box size="0.042 0.061 0.042"/>
        </geometry>
        <origin rpy="0 0 0" xyz="0 0 0"/>
        <material name="silver">
          <color rgba="0.5 0.5 0.5 1"/>
        </material>
      </visual>
      <collision>
        <geometry>
          <box size="0.042 0.042 0.042"/>
        </geometry>
        <origin rpy="0 0 0" xyz="0 0 0"/>
      </collision>
      <inertial>
          <mass value="1"/>
          <inertia ixx="1.0" ixy="0.0" ixz="0.0" iyy="1.0" iyz="0.0" izz="1.0"/>
      </inertial>
    </link>
    
    <link name="servo_hip_pitch_kiri">
      <visual>
        <geometry>
          <box size="0.042 0.042 0.061"/>
        </geometry>
        <origin rpy="0 0 0" xyz="0 -0.03 0"/>
        <material name="silver">
          <color rgba="0.5 0.5 0.5 1"/>
        </material>
      </visual>
      <collision>
        <geometry>
          <box size="0.042 0.042 0.042"/>
        </geometry>
        <origin rpy="0 0 0" xyz="0 0 0"/>
      </collision>
      <inertial>
          <mass value="1"/>
          <inertia ixx="1.0" ixy="0.0" ixz="0.0" iyy="1.0" iyz="0.0" izz="1.0"/>
      </inertial>
    </link>


    <link name="servo_hip_roll_kiri">
      <visual>
        <geometry>
          <box size="0.042 0.042 0.061"/>
        </geometry>
        <origin rpy="0 0 0" xyz="0 0 0"/>
        <material name="silver">
          <color rgba="0.5 0.5 0.5 1"/>
        </material>
      </visual>
      <collision>
        <geometry>
          <box size="0.042 0.042 0.042"/>
        </geometry>
        <origin rpy="0 0 0" xyz="0 0 0"/>
      </collision>
      <inertial>
          <mass value="1"/>
          <inertia ixx="1.0" ixy="0.0" ixz="0.0" iyy="1.0" iyz="0.0" izz="1.0"/>
      </inertial>
    </link>

    <link name="link_paha_kiri">
      <visual>
        <geometry>
          <box size="0.042 0.042 0.192"/>
        </geometry>
        <origin rpy="0 0 0" xyz="0 0 -0.09"/>
        <material name="silver">
          <color rgba="0.5 0.5 0.5 1"/>
        </material>
      </visual>
      <collision>
        <geometry>
          <box size="0.042 0.042 0.192"/>
        </geometry>
        <origin rpy="0 0 0" xyz="0 0 -0.09"/>
      </collision>
      <inertial>
          <mass value="1"/>
          <inertia ixx="1.0" ixy="0.0" ixz="0.0" iyy="1.0" iyz="0.0" izz="1.0"/>
      </inertial>
    </link>

    <joint name="link_servo_lutut_kiri" type="fixed">
        <parent link="link_paha_kiri"/>
        <child link="servo_lutut_kiri"/>
        <origin xyz="0 0.0 -0.15"/>
        <axis xyz="1 0 0" />
        <limit effort="300" velocity="0.1" lower="-1.57" upper="1.57"/>
    </joint>

    <link name="servo_lutut_kiri">
      <visual>
        <geometry>
          <box size="0.042 0.042 0.061"/>
        </geometry>
        <origin rpy="0 0 0" xyz="0 0 0"/>
        <material name="silver">
          <color rgba="0.5 0.5 0.5 1"/>
        </material>
      </visual>
      <collision>
        <geometry>
          <box size="0.042 0.042 0.061"/>
        </geometry>
        <origin rpy="0 0 0" xyz="0 0 0"/>
      </collision>
      <inertial>
          <mass value="1"/>
          <inertia ixx="1.0" ixy="0.0" ixz="0.0" iyy="1.0" iyz="0.0" izz="1.0"/>
      </inertial>
    </link>

    <link name="link_betis_kiri">
      <visual>
        <geometry>
          <box size="0.042 0.042 0.192"/>
        </geometry>
        <origin rpy="0 0 0" xyz="0 0 -0.09"/>
        <material name="silver">
          <color rgba="0.5 0.5 0.5 11"/>
        </material>
      </visual>
      <collision>
        <geometry>
          <box size="0.042 0.042 0.192"/>
        </geometry>
        <origin rpy="0 0 0" xyz="0 0 -0.09"/>
      </collision>
      <inertial>
          <mass value="1"/>
          <inertia ixx="1.0" ixy="0.0" ixz="0.0" iyy="1.0" iyz="0.0" izz="1.0"/>
      </inertial>
    </link>

    <link name="servo_engkle_roll_kiri">
      <visual>
        <geometry>
          <box size="0 0 0"/>
        </geometry>
        <origin rpy="0 0 0" xyz="0 0 0"/>
        <material name="silver">
          <color rgba="0.5 0.5 0.5 1"/>
        </material>
      </visual>
      <collision>
        <geometry>
          <box size="0 0 0"/>
        </geometry>
        <origin rpy="0 0 0" xyz="0 0 0"/>
      </collision>
      <inertial>
          <mass value="1"/>
          <inertia ixx="1.0" ixy="0.0" ixz="0.0" iyy="1.0" iyz="0.0" izz="1.0"/>
      </inertial>
    </link>

    <joint name="link_servo_engkle_kiri" type="fixed">
        <parent link="servo_engkle_roll_kiri"/>
        <child link="servo_engkle_pitch_kiri"/>
        <origin xyz="0 -0.051 0"/>
        <axis xyz="1 0 0" />
        <limit effort="300" velocity="0.1" lower="-3.14" upper="3.14"/>
    </joint>

    <link name="servo_engkle_pitch_kiri">
      <visual>
        <geometry>
          <box size="0.042 0.042 0.061"/>
        </geometry>
        <origin rpy="0 0 0" xyz="0 0 0"/>
        <material name="silver">
          <color rgba="0.5 0.5 0.5 1"/>
        </material>
      </visual>
      <collision>
        <geometry>
          <box size="0.042 0.042 0.061"/>
        </geometry>
        <origin rpy="0 0 0" xyz="0 0 0"/>
      </collision>
      <inertial>
          <mass value="1"/>
          <inertia ixx="1.0" ixy="0.0" ixz="0.0" iyy="1.0" iyz="0.0" izz="1.0"/>
      </inertial>
    </link>

    <link name="telapak_kaki_kiri">
      <visual>
        <geometry>
          <box size="0.129 0.219 0.005"/>
        </geometry>
        <origin rpy="0 0 0" xyz="-0.0170 0 -0.056"/>
        <material name="silver">
          <color rgba="0.5 0.5 0.5 1"/>
        </material>
      </visual>
      <collision>
        <geometry>
          <box size="0.129 0.219 0.005"/>
        </geometry>
        <origin rpy="0 0 0" xyz="-0.0170 0 -0.056"/>
      </collision>
      <inertial>
          <mass value="1"/>
          <inertia ixx="1.0" ixy="0.0" ixz="0.0" iyy="1.0" iyz="0.0" izz="1.0"/>
      </inertial>
    </link>

    <joint name="kaki_kiri_eof" type="fixed">
        <parent link="telapak_kaki_kiri"/>
        <child link="telapak_kaki_kiri_eof"/>
        <origin xyz="0 0.0 -0.055"/>
        <axis xyz="0 1 0" />
        <limit effort="300" velocity="0.1" lower="-3.14" upper="3.14"/>
    </joint>

    <link name="telapak_kaki_kiri_eof">
      <visual>
        <geometry>
          <box size="0.129 0.005 0.030"/>
        </geometry>
        <origin rpy="0 0 0" xyz="-0.0170 0.107 0.017"/>
            <material name="black">
                <color rgba="0 0 0 1"/>
            </material>
      </visual>
      <collision>
        <geometry>
          <box size="0.129 0.005 0.030"/>
        </geometry>
        <origin rpy="0 0 0" xyz="-0.0170 0.107 0.017"/>
      </collision>
      <inertial>
          <mass value="1"/>
          <inertia ixx="1.0" ixy="0.0" ixz="0.0" iyy="1.0" iyz="0.0" izz="1.0"/>
      </inertial>
    </link>

</robot>
