<?xml version="1.0" ?>
<!-- =================================================================================== -->
<!-- |    This document was autogenerated by xacro from tflow_new.xacro                | -->
<!-- |    EDITING THIS FILE BY HAND IS NOT RECOMMENDED                                 | -->
<!-- =================================================================================== -->
<robot name="tflow" xmlns:xacro="http://ros.org/wiki/xacro">
  <link name="base_link">
    <visual>
      <geometry>
        <box size="0.19 0.16 0.06"/>
      </geometry>
      <origin rpy="0 0 0" xyz="0 0 0"/>
      <material name="silver">
        <color rgba="0.5 0.5 0.5 1"/>
      </material>
    </visual>
    <collision>
      <geometry>
        <box size="0.19 0.16 0.06"/>
      </geometry>
      <origin rpy="0 0 0" xyz="0 0 0"/>
      <material name="silver">
        <color rgba="0.5 0.5 0.5 1"/>
      </material>
    </collision>
    <inertial>
      <mass value="0.01"/>
      <inertia ixx="0.0" ixy="0.0" ixz="0.0" iyy="0.0" iyz="0.0" izz="0.0"/>
    </inertial>
  </link>
  <!-- PERUT -->
  <link name="servo_perut_pitch">
    <visual>
      <geometry>
        <box size="0.0402 0.046 0.0651"/>
      </geometry>
      <origin rpy="0.0 0.0 1.57" xyz="0 0 0.025"/>
      <material name="silver">
        <color rgba="0.3 0.3 0.3 1"/>
      </material>
    </visual>
    <collision>
      <geometry>
        <box size="0.0402 0.046 0.0651"/>
      </geometry>
      <origin rpy="0.0 0.0 1.57" xyz="0 0 0.025"/>
    </collision>
    <inertial>
      <mass value="0.153"/>
      <inertia ixx="0.0" ixy="0.0" ixz="0.0" iyy="0.0" iyz="0.0" izz="0.0"/>
    </inertial>
  </link>
  <link name="servo_perut_roll">
    <visual>
      <geometry>
        <box size="0.0402 0.046 0.0651"/>
      </geometry>
      <origin rpy="0.0 0.0 1.57" xyz="0 0 0.025"/>
      <material name="silver">
        <color rgba="0.3 0.3 0.3 1"/>
      </material>
    </visual>
    <collision>
      <geometry>
        <box size="0.0402 0.046 0.0651"/>
      </geometry>
      <origin rpy="0.0 0.0 1.57" xyz="0 0 0.025"/>
    </collision>
    <inertial>
      <mass value="0.153"/>
      <inertia ixx="0.0" ixy="0.0" ixz="0.0" iyy="0.0" iyz="0.0" izz="0.0"/>
    </inertial>
  </link>
  <link name="badan_atas">
    <visual>
      <geometry>
        <box size="0.174 0.115 0.086"/>
      </geometry>
      <origin rpy="0.0 0.0 0" xyz="0 -0.04 0.0715"/>
      <material name="white">
        <color rgba="0.8 0.8 0.8 1"/>
      </material>
    </visual>
    <collision>
      <geometry>
        <box size="0.174 0.115 0.086"/>
      </geometry>
      <origin rpy="0.0 0.0 0" xyz="0 -0.04 0.0715"/>
    </collision>
    <inertial>
      <mass value="0.00172086"/>
      <inertia ixx="0.0" ixy="0.0" ixz="0.0" iyy="0.0" iyz="0.0" izz="0.0"/>
    </inertial>
  </link>
  <!-- PERUT -->
  <joint name="joint_perut_pitch" type="revolute">
    <parent link="base_link"/>
    <child link="servo_perut_pitch"/>
    <origin rpy="0 0 0" xyz="0.00 -0.01 0.061"/>
    <limit effort="300" lower="-1.57" upper="1.57" velocity="0.1"/>
    <dynamics damping="50" friction="1"/>
    <axis xyz="0 1 0"/>
  </joint>
  <joint name="servo_joint_perut_roll" type="fixed">
    <parent link="servo_perut_pitch"/>
    <child link="servo_perut_roll"/>
    <origin rpy="0 0 0" xyz="0.00 0.05 0.00"/>
    <limit effort="300" lower="-1.57" upper="1.57" velocity="0.1"/>
    <dynamics damping="50" friction="1"/>
    <axis xyz="1 0 0"/>
  </joint>
  <joint name="joint_perut_roll" type="revolute">
    <parent link="servo_perut_roll"/>
    <child link="badan_atas"/>
    <origin rpy="0 0 0" xyz="0.00 0.0 0.0451"/>
    <limit effort="300" lower="-1.57" upper="1.57" velocity="0.1"/>
    <dynamics damping="50" friction="1"/>
    <axis xyz="1 0 0"/>
  </joint>
  <!-- Kaki Kanan -->
  <joint name="base_to_hip_kanan" type="fixed">
    <parent link="base_link"/>
    <child link="servo_hip_yaw_kanan"/>
    <origin xyz="0.053 0 0."/>
    <axis xyz="0 0 1"/>
  </joint>
  <link name="servo_hip_yaw_kanan">
    <visual>
      <geometry>
        <box size="0.042 0.061 0.042"/>
      </geometry>
      <origin rpy="0 0 0" xyz="0 0 0"/>
      <material name="silver">
        <color rgba="0.5 0.5 0.5 1"/>
      </material>
    </visual>
    <collision>
      <geometry>
        <box size="0.042 0.042 0.042"/>
      </geometry>
      <origin rpy="0 0 0" xyz="0 0 0"/>
    </collision>
    <inertial>
      <mass value="1"/>
      <inertia ixx="1.0" ixy="0.0" ixz="0.0" iyy="1.0" iyz="0.0" izz="1.0"/>
    </inertial>
  </link>
  <joint name="7.hip_kanan_yaw" type="revolute">
    <parent link="servo_hip_yaw_kanan"/>
    <child link="servo_hip_pitch_kanan"/>
    <origin xyz="0 0 -0.060"/>
    <axis xyz="0 0 -1"/>
    <limit effort="300" lower="-1.57" upper="1.57" velocity="0.1"/>
  </joint>
  <link name="servo_hip_pitch_kanan">
    <visual>
      <geometry>
        <box size="0.042 0.042 0.061"/>
      </geometry>
      <origin rpy="0 0 0" xyz="0 -0.03 0"/>
      <material name="silver">
        <color rgba="0.5 0.5 0.5 1"/>
      </material>
    </visual>
    <collision>
      <geometry>
        <box size="0.042 0.042 0.042"/>
      </geometry>
      <origin rpy="0 0 0" xyz="0 0 0"/>
    </collision>
    <inertial>
      <mass value="1"/>
      <inertia ixx="1.0" ixy="0.0" ixz="0.0" iyy="1.0" iyz="0.0" izz="1.0"/>
    </inertial>
  </link>
  <joint name="9.hip_kanan_pitch" type="revolute">
    <parent link="servo_hip_pitch_kanan"/>
    <child link="servo_hip_roll_kanan"/>
    <origin xyz="0 0.02 0"/>
    <axis xyz="0 -1 0"/>
    <limit effort="300" lower="-1.57" upper="1.57" velocity="0.1"/>
  </joint>
  <link name="servo_hip_roll_kanan">
    <visual>
      <geometry>
        <box size="0.042 0.042 0.061"/>
      </geometry>
      <origin rpy="0 0 0" xyz="0 0 0"/>
      <material name="silver">
        <color rgba="0.5 0.5 0.5 1"/>
      </material>
    </visual>
    <collision>
      <geometry>
        <box size="0.042 0.042 0.042"/>
      </geometry>
      <origin rpy="0 0 0" xyz="0 0 0"/>
    </collision>
    <inertial>
      <mass value="1"/>
      <inertia ixx="1.0" ixy="0.0" ixz="0.0" iyy="1.0" iyz="0.0" izz="1.0"/>
    </inertial>
  </link>
  <joint name="11.hip_kanan_roll" type="revolute">
    <parent link="servo_hip_roll_kanan"/>
    <child link="link_paha_kanan"/>
    <origin xyz="0 0.0 -0.01"/>
    <axis xyz="1 0 0"/>
    <limit effort="300" lower="-1.57" upper="1.57" velocity="0.1"/>
  </joint>
  <link name="link_paha_kanan">
    <visual>
      <geometry>
        <box size="0.042 0.042 0.192"/>
      </geometry>
      <origin rpy="0 0 0" xyz="0 0 -0.09"/>
      <material name="silver">
        <color rgba="0.5 0.5 0.5 1"/>
      </material>
    </visual>
    <collision>
      <geometry>
        <box size="0.042 0.042 0.192"/>
      </geometry>
      <origin rpy="0 0 0" xyz="0 0 -0.09"/>
    </collision>
    <inertial>
      <mass value="1"/>
      <inertia ixx="1.0" ixy="0.0" ixz="0.0" iyy="1.0" iyz="0.0" izz="1.0"/>
    </inertial>
  </link>
  <joint name="link_servo_lutut_kanan" type="fixed">
    <parent link="link_paha_kanan"/>
    <child link="servo_lutut_kanan"/>
    <origin xyz="0 0.0 -0.15 "/>
    <axis xyz="1 0 0"/>
    <limit effort="300" lower="-1.57" upper="1.57" velocity="0.1"/>
  </joint>
  <link name="servo_lutut_kanan">
    <visual>
      <geometry>
        <box size="0.042 0.042 0.061"/>
      </geometry>
      <origin rpy="0 0 0" xyz="0 0 0"/>
      <material name="silver">
        <color rgba="0.5 0.5 0.5 1"/>
      </material>
    </visual>
    <collision>
      <geometry>
        <box size="0.042 0.042 0.061"/>
      </geometry>
      <origin rpy="0 0 0" xyz="0 0 0"/>
    </collision>
    <inertial>
      <mass value="1"/>
      <inertia ixx="1.0" ixy="0.0" ixz="0.0" iyy="1.0" iyz="0.0" izz="1.0"/>
    </inertial>
  </link>
  <joint name="13.lutut_kanan_roll" type="revolute">
    <parent link="servo_lutut_kanan"/>
    <child link="link_betis_kanan"/>
    <origin xyz="0 0.0 -0.022"/>
    <axis xyz="1 0 0"/>
    <limit effort="300" lower="-3.14" upper="3.14" velocity="0.1"/>
  </joint>
  <link name="link_betis_kanan">
    <visual>
      <geometry>
        <box size="0.042 0.042 0.192"/>
      </geometry>
      <origin rpy="0 0 0" xyz="0 0 -0.09"/>
      <material name="silver">
        <color rgba="0.5 0.5 0.5 11"/>
      </material>
    </visual>
    <collision>
      <geometry>
        <box size="0.042 0.042 0.192"/>
      </geometry>
      <origin rpy="0 0 0" xyz="0 0 -0.09"/>
    </collision>
    <inertial>
      <mass value="1"/>
      <inertia ixx="1.0" ixy="0.0" ixz="0.0" iyy="1.0" iyz="0.0" izz="1.0"/>
    </inertial>
  </link>
  <joint name="15.engkle_kanan_roll" type="revolute">
    <parent link="link_betis_kanan"/>
    <child link="servo_engkle_roll_kanan"/>
    <origin xyz="0 0.0 -0.15"/>
    <axis xyz="-1 0 0"/>
    <limit effort="300" lower="-1.57" upper="1.57" velocity="0.1"/>
  </joint>
  <link name="servo_engkle_roll_kanan">
    <visual>
      <geometry>
        <box size="0 0 0"/>
      </geometry>
      <origin rpy="0 0 0" xyz="0 0 0"/>
      <material name="silver">
        <color rgba="0.5 0.5 0.5 1"/>
      </material>
    </visual>
    <collision>
      <geometry>
        <box size="0 0 0"/>
      </geometry>
      <origin rpy="0 0 0" xyz="0 0 0"/>
    </collision>
    <inertial>
      <mass value="1"/>
      <inertia ixx="1.0" ixy="0.0" ixz="0.0" iyy="1.0" iyz="0.0" izz="1.0"/>
    </inertial>
  </link>
  <joint name="link_servo_engkle_kanan" type="fixed">
    <parent link="servo_engkle_roll_kanan"/>
    <child link="servo_engkle_pitch_kanan"/>
    <origin xyz="0 -0.051 0"/>
    <axis xyz="1 0 0"/>
    <limit effort="300" lower="-3.14" upper="3.14" velocity="0.1"/>
  </joint>
  <link name="servo_engkle_pitch_kanan">
    <visual>
      <geometry>
        <box size="0.042 0.042 0.061"/>
      </geometry>
      <origin rpy="0 0 0" xyz="0 0 0"/>
      <material name="silver">
        <color rgba="0.5 0.5 0.5 1"/>
      </material>
    </visual>
    <collision>
      <geometry>
        <box size="0.042 0.042 0.061"/>
      </geometry>
      <origin rpy="0 0 0" xyz="0 0 0"/>
    </collision>
    <inertial>
      <mass value="1"/>
      <inertia ixx="1.0" ixy="0.0" ixz="0.0" iyy="1.0" iyz="0.0" izz="1.0"/>
    </inertial>
  </link>
  <joint name="17.telapak_kaki_kanan_pitch" type="revolute">
    <parent link="servo_engkle_pitch_kanan"/>
    <child link="telapak_kaki_kanan"/>
    <origin xyz="0 0.025 0"/>
    <axis xyz="0 1 0"/>
    <limit effort="300" lower="-0.54" upper="0.54" velocity="0.1"/>
  </joint>
  <link name="telapak_kaki_kanan">
    <visual>
      <geometry>
        <box size="0.129 0.219 0.005"/>
      </geometry>
      <origin rpy="0 0 0" xyz="0.0170 0 -0.056"/>
      <material name="silver">
        <color rgba="0.5 0.5 0.5 1"/>
      </material>
    </visual>
    <collision>
      <geometry>
        <box size="0.129 0.219 0.005"/>
      </geometry>
      <origin rpy="0 0 0" xyz="0.0170 0 -0.056"/>
    </collision>
    <inertial>
      <mass value="1"/>
      <inertia ixx="1.0" ixy="0.0" ixz="0.0" iyy="1.0" iyz="0.0" izz="1.0"/>
    </inertial>
  </link>
  <joint name="kaki_kanan_eof" type="fixed">
    <parent link="telapak_kaki_kanan"/>
    <child link="telapak_kaki_kanan_eof"/>
    <origin xyz="0 0.0 -0.055"/>
    <axis xyz="0 1 0"/>
    <limit effort="300" lower="-3.14" upper="3.14" velocity="0.1"/>
  </joint>
  <link name="telapak_kaki_kanan_eof">
    <visual>
      <geometry>
        <box size="0.129 0.005 0.030"/>
      </geometry>
      <origin rpy="0 0 0" xyz="0.0170 0.107 0.017"/>
      <material name="silver">
        <color rgba="0.5 0.5 0.5 1"/>
      </material>
    </visual>
    <collision>
      <geometry>
        <box size="0.129 0.005 0.030"/>
      </geometry>
      <origin rpy="0 0 0" xyz="0.0170 0.107 0.017"/>
    </collision>
    <inertial>
      <mass value="1"/>
      <inertia ixx="1.0" ixy="0.0" ixz="0.0" iyy="1.0" iyz="0.0" izz="1.0"/>
    </inertial>
  </link>
  <!--Kaki kiri-->
  <joint name="base_to_hip_kiri" type="fixed">
    <parent link="base_link"/>
    <child link="servo_hip_yaw_kiri"/>
    <origin xyz="-0.053 0 0"/>
    <axis xyz="0 0 1"/>
  </joint>
  <link name="servo_hip_yaw_kiri">
    <visual>
      <geometry>
        <box size="0.042 0.061 0.042"/>
      </geometry>
      <origin rpy="0 0 0" xyz="0 0 0"/>
      <material name="silver">
        <color rgba="0.5 0.5 0.5 1"/>
      </material>
    </visual>
    <collision>
      <geometry>
        <box size="0.042 0.042 0.042"/>
      </geometry>
      <origin rpy="0 0 0" xyz="0 0 0"/>
    </collision>
    <inertial>
      <mass value="1"/>
      <inertia ixx="1.0" ixy="0.0" ixz="0.0" iyy="1.0" iyz="0.0" izz="1.0"/>
    </inertial>
  </link>
  <joint name="8.hip_kiri_yaw" type="revolute">
    <parent link="servo_hip_yaw_kiri"/>
    <child link="servo_hip_pitch_kiri"/>
    <origin xyz="0 0 -0.060"/>
    <axis xyz="0 0 -1"/>
    <limit effort="300" lower="-1.57" upper="1.57" velocity="0.1"/>
  </joint>
  <link name="servo_hip_pitch_kiri">
    <visual>
      <geometry>
        <box size="0.042 0.042 0.061"/>
      </geometry>
      <origin rpy="0 0 0" xyz="0 -0.03 0"/>
      <material name="silver">
        <color rgba="0.5 0.5 0.5 1"/>
      </material>
    </visual>
    <collision>
      <geometry>
        <box size="0.042 0.042 0.042"/>
      </geometry>
      <origin rpy="0 0 0" xyz="0 0 0"/>
    </collision>
    <inertial>
      <mass value="1"/>
      <inertia ixx="1.0" ixy="0.0" ixz="0.0" iyy="1.0" iyz="0.0" izz="1.0"/>
    </inertial>
  </link>
  <joint name="10.hip_kiri_pitch" type="revolute">
    <parent link="servo_hip_pitch_kiri"/>
    <child link="servo_hip_roll_kiri"/>
    <origin xyz="0 0.02 0"/>
    <axis xyz="0 -1 0"/>
    <limit effort="300" lower="-1.57" upper="1.57" velocity="0.1"/>
  </joint>
  <link name="servo_hip_roll_kiri">
    <visual>
      <geometry>
        <box size="0.042 0.042 0.061"/>
      </geometry>
      <origin rpy="0 0 0" xyz="0 0 0"/>
      <material name="silver">
        <color rgba="0.5 0.5 0.5 1"/>
      </material>
    </visual>
    <collision>
      <geometry>
        <box size="0.042 0.042 0.042"/>
      </geometry>
      <origin rpy="0 0 0" xyz="0 0 0"/>
    </collision>
    <inertial>
      <mass value="1"/>
      <inertia ixx="1.0" ixy="0.0" ixz="0.0" iyy="1.0" iyz="0.0" izz="1.0"/>
    </inertial>
  </link>
  <joint name="12.hip_kiri_roll" type="revolute">
    <parent link="servo_hip_roll_kiri"/>
    <child link="link_paha_kiri"/>
    <origin xyz="0 0.0 0"/>
    <axis xyz="-1 0 0"/>
    <limit effort="300" lower="-1.57" upper="1.57" velocity="0.1"/>
  </joint>
  <link name="link_paha_kiri">
    <visual>
      <geometry>
        <box size="0.042 0.042 0.192"/>
      </geometry>
      <origin rpy="0 0 0" xyz="0 0 -0.09"/>
      <material name="silver">
        <color rgba="0.5 0.5 0.5 1"/>
      </material>
    </visual>
    <collision>
      <geometry>
        <box size="0.042 0.042 0.192"/>
      </geometry>
      <origin rpy="0 0 0" xyz="0 0 -0.09"/>
    </collision>
    <inertial>
      <mass value="1"/>
      <inertia ixx="1.0" ixy="0.0" ixz="0.0" iyy="1.0" iyz="0.0" izz="1.0"/>
    </inertial>
  </link>
  <joint name="link_servo_lutut_kiri" type="fixed">
    <parent link="link_paha_kiri"/>
    <child link="servo_lutut_kiri"/>
    <origin xyz="0 0.0 -0.15"/>
    <axis xyz="1 0 0"/>
    <limit effort="300" lower="-1.57" upper="1.57" velocity="0.1"/>
  </joint>
  <link name="servo_lutut_kiri">
    <visual>
      <geometry>
        <box size="0.042 0.042 0.061"/>
      </geometry>
      <origin rpy="0 0 0" xyz="0 0 0"/>
      <material name="silver">
        <color rgba="0.5 0.5 0.5 1"/>
      </material>
    </visual>
    <collision>
      <geometry>
        <box size="0.042 0.042 0.061"/>
      </geometry>
      <origin rpy="0 0 0" xyz="0 0 0"/>
    </collision>
    <inertial>
      <mass value="1"/>
      <inertia ixx="1.0" ixy="0.0" ixz="0.0" iyy="1.0" iyz="0.0" izz="1.0"/>
    </inertial>
  </link>
  <!--
    <joint name="14.lutut_kiri_roll" type="revolute">
        <parent link="servo_lutut_kiri"/>
        <child link="link_betis_kiri"/>
        <origin xyz="0 0.0 -0.022"/>
        <axis xyz="-1 0 0" />
        <limit effort="300" velocity="0.1" lower="-3.14" upper="3.14"/>
    </joint>

    <link name="link_betis_kiri">
      <visual>
        <geometry>
          <box size="0.042 0.042 0.192"/>
        </geometry>
        <origin rpy="0 0 0" xyz="0 0 -0.09"/>
        <material name="silver">
          <color rgba="0.5 0.5 0.5 11"/>
        </material>
      </visual>
      <collision>
        <geometry>
          <box size="0.042 0.042 0.192"/>
        </geometry>
        <origin rpy="0 0 0" xyz="0 0 -0.09"/>
      </collision>
      <inertial>
          <mass value="1"/>
          <inertia ixx="1.0" ixy="0.0" ixz="0.0" iyy="1.0" iyz="0.0" izz="1.0"/>
      </inertial>
    </link>

    <joint name="16.engkle_kiri_roll" type="revolute">
        <parent link="link_betis_kiri"/>
        <child link="servo_engkle_roll_kiri"/>
        <origin xyz="0 0.0 -0.15"/>
        <axis xyz="1 0 0" />
        <limit effort="300" velocity="0.1" lower="-1.57" upper="1.57"/>
    </joint>

    <link name="servo_engkle_roll_kiri">
      <visual>
        <geometry>
          <box size="0 0 0"/>
        </geometry>
        <origin rpy="0 0 0" xyz="0 0 0"/>
        <material name="silver">
          <color rgba="0.5 0.5 0.5 1"/>
        </material>
      </visual>
      <collision>
        <geometry>
          <box size="0 0 0"/>
        </geometry>
        <origin rpy="0 0 0" xyz="0 0 0"/>
      </collision>
      <inertial>
          <mass value="1"/>
          <inertia ixx="1.0" ixy="0.0" ixz="0.0" iyy="1.0" iyz="0.0" izz="1.0"/>
      </inertial>
    </link>

    <joint name="link_servo_engkle_kiri" type="fixed">
        <parent link="servo_engkle_roll_kiri"/>
        <child link="servo_engkle_pitch_kiri"/>
        <origin xyz="0 -0.051 0"/>
        <axis xyz="1 0 0" />
        <limit effort="300" velocity="0.1" lower="-3.14" upper="3.14"/>
    </joint>

    <link name="servo_engkle_pitch_kiri">
      <visual>
        <geometry>
          <box size="0.042 0.042 0.061"/>
        </geometry>
        <origin rpy="0 0 0" xyz="0 0 0"/>
        <material name="silver">
          <color rgba="0.5 0.5 0.5 1"/>
        </material>
      </visual>
      <collision>
        <geometry>
          <box size="0.042 0.042 0.061"/>
        </geometry>
        <origin rpy="0 0 0" xyz="0 0 0"/>
      </collision>
      <inertial>
          <mass value="1"/>
          <inertia ixx="1.0" ixy="0.0" ixz="0.0" iyy="1.0" iyz="0.0" izz="1.0"/>
      </inertial>
    </link>

    <joint name="18.telapak_kaki_kiri_pitch" type="revolute">
        <parent link="servo_engkle_pitch_kiri"/>
        <child link="telapak_kaki_kiri"/>
        <origin xyz="0 0.025 0"/>
        <axis xyz="0 1 0" />
        <limit effort="300" velocity="0.1" lower="-0.54" upper="0.54"/>
    </joint>

    <link name="telapak_kaki_kiri">
      <visual>
        <geometry>
          <box size="0.129 0.219 0.005"/>
        </geometry>
        <origin rpy="0 0 0" xyz="-0.0170 0 -0.056"/>
        <material name="silver">
          <color rgba="0.5 0.5 0.5 1"/>
        </material>
      </visual>
      <collision>
        <geometry>
          <box size="0.129 0.219 0.005"/>
        </geometry>
        <origin rpy="0 0 0" xyz="-0.0170 0 -0.056"/>
      </collision>
      <inertial>
          <mass value="1"/>
          <inertia ixx="1.0" ixy="0.0" ixz="0.0" iyy="1.0" iyz="0.0" izz="1.0"/>
      </inertial>
    </link>

    <joint name="kaki_kiri_eof" type="fixed">
        <parent link="telapak_kaki_kiri"/>
        <child link="telapak_kaki_kiri_eof"/>
        <origin xyz="0 0.0 -0.055"/>
        <axis xyz="0 1 0" />
        <limit effort="300" velocity="0.1" lower="-3.14" upper="3.14"/>
    </joint>

    <link name="telapak_kaki_kiri_eof">
      <visual>
        <geometry>
          <box size="0.129 0.005 0.030"/>
        </geometry>
        <origin rpy="0 0 0" xyz="-0.0170 0.107 0.017"/>
        <material name="silver">
          <color rgba="0.5 0.5 0.5 1"/>
        </material>
      </visual>
      <collision>
        <geometry>
          <box size="0.129 0.005 0.030"/>
        </geometry>
        <origin rpy="0 0 0" xyz="-0.0170 0.107 0.017"/>
      </collision>
      <inertial>
          <mass value="1"/>
          <inertia ixx="1.0" ixy="0.0" ixz="0.0" iyy="1.0" iyz="0.0" izz="1.0"/>
      </inertial>
    </link>
-->
</robot>

